Workbook
Name 选择: #REF!
Name 架空线路停电清抹玻璃绝缘子: #REF!

Sheet 风险评估模型1（单张票作业）
A1: 输电管理所场景式持续作业风险评估模型
A3: 工作任务风险值（F） | H3: =IF(I3<20,"可接受",IF(I3<70,"低风险",IF(I3<200,"中风险",IF(I3<400,"高风险","特高风险")))) -> 低风险 | I3: =SUM(I7,I11,I26) -> 58
A4: 设备运维班组 | B4: 500kV输电线路一班 | E4: 施工单位 | F4: 中国能源建设集团广东火电工程有限公司
A5: 工作任务 | B5: 同塔架设的500kV上渡甲线（色标：蓝色）、500kV上渡乙线（色标：黄色）更换N100塔-N177塔杆号牌、机巡牌 | F5: 工作负责人及联系电话 | G5: 戴德富19977892180 | H5: 作业人数 | I5: =SUM(F12:F18) -> 11
A6: 工作开始时间 | B6: 45445 | D6: 工作结束时间 | E6: 45459 | G6: 工期 | H6: =_xlfn.DAYS(E6+1,B6) -> 15
A7: 作业类型风险值（Amax*an） | I7: =MAX(F9:F10)*I9 -> 20
B8: 作业项目 | F8: 基准风险值评分（A） | G8: 基准风险级别 | H8: 作业项目数 | I8: 调整系数an
A9: 工作任务1 | B9: 项目1 | C9: 架空线路带电补装或更换杆塔标示牌 | F9: =IF(ISERROR(VLOOKUP(C9,'典型作业项目库（不能删除）'!$C$4:$D$199,2,FALSE)),0,VLOOKUP(C9,'典型作业项目库（不能删除）'!$C$4:$D$199,2,FALSE)) -> 20 | G9: =IF(F9<20,"可接受",IF(F9<70,"低风险",IF(F9<200,"中风险",IF(F9<400,"高风险","特高风险")))) -> 低风险 | H9: =COUNTA(C9:E10) -> 1 | I9: =IF(H9=1,1,IF(H9<4,1.1,IF(H9>3,1.2))) -> 1
B10: 项目2 | F10: =IF(ISERROR(VLOOKUP(C10,'典型作业项目库（不能删除）'!$C$4:$D$199,2,FALSE)),0,VLOOKUP(C10,'典型作业项目库（不能删除）'!$C$4:$D$199,2,FALSE)) -> 0 | G10: =IF(F10<20,"可接受",IF(F10<70,"低风险",IF(F10<200,"中风险",IF(F10<400,"高风险","特高风险")))) -> 可接受
A11: 作业人员能力评分表（B） | I11: =SUM(I12:I25) -> 11
A12: 工作任务1 | B12: 评分B1 | C12: ='作业人员能力（不能删除）'!A3 -> 工作负责人（含小组工作负责人）安全意识 | E12: 查询系统，核实录入违章人数 | F12: 1 | G12: 3年内0-2次D类违章0分 | I12: =IF(ISERROR(VLOOKUP(G12,'作业人员能力（不能删除）'!$A$4:$B$8,2,FALSE)),0,VLOOKUP(G12,'作业人员能力（不能删除）'!$A$4:$B$8,2,FALSE)) -> 0
B13: 评分B2 | C13: ='作业人员能力（不能删除）'!C3 -> 主要工作班成员（辅助工除外）安全意识 | F13: 10 | G13: 3年内0-2次D类违章0分 | I13: =IF(ISERROR(VLOOKUP(G13,'作业人员能力（不能删除）'!$C$4:$D$8,2,FALSE)),0,VLOOKUP(G13,'作业人员能力（不能删除）'!$C$4:$D$8,2,FALSE))*F13 -> 0
F14: 0 | G14: 3年内累计3次及以上D类违章的，每人计2分 | I14: =IF(ISERROR(VLOOKUP(G14,'作业人员能力（不能删除）'!$C$4:$D$8,2,FALSE)),0,VLOOKUP(G14,'作业人员能力（不能删除）'!$C$4:$D$8,2,FALSE))*F14 -> 0
F15: 0 | G15: 3年内累计1次及以上C类违章的，每人计3分 | I15: =IF(ISERROR(VLOOKUP(G15,'作业人员能力（不能删除）'!$C$4:$D$8,2,FALSE)),0,VLOOKUP(G15,'作业人员能力（不能删除）'!$C$4:$D$8,2,FALSE))*F15 -> 0
F16: 0 | G16: 3年内累计1次以上B类违章的，每人计5分 | I16: =IF(ISERROR(VLOOKUP(G16,'作业人员能力（不能删除）'!$C$4:$D$8,2,FALSE)),0,VLOOKUP(G16,'作业人员能力（不能删除）'!$C$4:$D$8,2,FALSE))*F16 -> 0
F17: 0 | G17: 3年内累计1次及以上A类违章的，每人计6分 | I17: =IF(ISERROR(VLOOKUP(G17,'作业人员能力（不能删除）'!$C$4:$D$8,2,FALSE)),0,VLOOKUP(G17,'作业人员能力（不能删除）'!$C$4:$D$8,2,FALSE))*F17 -> 0
B18: 评分B3 | C18: ='作业人员能力（不能删除）'!E3 -> 监护人（含专职监护人）安全意识 | F18: 0 | G18: 3年内0-2次D类违章0分 | I18: =IF(ISERROR(VLOOKUP(G18,'作业人员能力（不能删除）'!$C$4:$D$8,2,FALSE)),0,VLOOKUP(G18,'作业人员能力（不能删除）'!$C$4:$D$8,2,FALSE))*F18 -> 0
B19: 评分B4 | C19: ='作业人员能力（不能删除）'!G3 -> 作业总人数 | E19: 超过8人但不足16人的，计3分 | I19: =IF(ISERROR(VLOOKUP(E19,'作业人员能力（不能删除）'!$G$4:$H$9,2,FALSE)),0,VLOOKUP(E19,'作业人员能力（不能删除）'!$G$4:$H$9,2,FALSE)) -> 3
B20: 评分B5 | C20: ='作业人员能力（不能删除）'!I3 -> 作业人员临时变更 | E20: 工作负责人在作业前（含工作间断后）1日确认的，计0分 | I20: =IF(ISERROR(VLOOKUP(E20,'作业人员能力（不能删除）'!$I$4:$J$5,2,FALSE)),0,VLOOKUP(E20,'作业人员能力（不能删除）'!$I$4:$J$5,2,FALSE)) -> 0
B21: 评分B6 | C21: ='作业人员能力（不能删除）'!K3 -> 人员性质 | E21: 外施工单位劳务分包人员，计8分 | I21: =IF(ISERROR(VLOOKUP(E21,'作业人员能力（不能删除）'!$K$4:$L$6,2,FALSE)),0,VLOOKUP(E21,'作业人员能力（不能删除）'!$K$4:$L$6,2,FALSE)) -> 8
B22: 评分B7 | C22: ='作业人员能力（不能删除）'!M3 -> 工作负责人（含小组工作负责人）组织同类型作业次数 | E22: 1年内2次及以上或2年内5次及以上的，每人计0分 | I22: =IF(ISERROR(VLOOKUP(E22,'作业人员能力（不能删除）'!$M$4:$N$8,2,FALSE)),0,VLOOKUP(E22,'作业人员能力（不能删除）'!$M$4:$N$8,2,FALSE)) -> 0
B23: 评分B8 | C23: ='作业人员能力（不能删除）'!O3 -> 主要工作班成员（辅助工除外）参与同类型作业次数 | E23: 1年内2次及以上或2年内5次及以上的，每人计0分 | I23: =IF(ISERROR(VLOOKUP(E23,'作业人员能力（不能删除）'!$O$4:$P$8,2,FALSE)),0,VLOOKUP(E23,'作业人员能力（不能删除）'!$O$4:$P$8,2,FALSE)) -> 0
B24: 评分B9 | C24: ='作业人员能力（不能删除）'!Q3 -> 监护人（含专职监护人）参与同类型作业次数 | E24: 1年内2次及以上或2年内5次及以上的，每人计0分 | I24: =IF(ISERROR(VLOOKUP(E24,'作业人员能力（不能删除）'!$Q$4:$R$8,2,FALSE)),0,VLOOKUP(E24,'作业人员能力（不能删除）'!$Q$4:$R$8,2,FALSE)) -> 0
B25: 评分B10 | C25: ='作业人员能力（不能删除）'!S3 -> 作业人员精神状态、疲劳程度 | E25: 良好，计0分 | I25: =IF(ISERROR(VLOOKUP(E25,'作业人员能力（不能删除）'!$S$4:$T$7,2,FALSE)),0,VLOOKUP(E25,'作业人员能力（不能删除）'!$S$4:$T$7,2,FALSE)) -> 0
A26: 作业环境和时间影响风险值评分表（C） | I26: =SUM(I27:I33) -> 27
A27: 工作任务1 | B27: 评分C1 | C27: ='作业环境和时间影响风险（不能删除）'!A3 -> 天气 | E27: 天气舒适，0分 | I27: =IF(ISERROR(VLOOKUP(E27,'作业环境和时间影响风险（不能删除）'!$A$4:$B$9,2,FALSE)),0,VLOOKUP(E27,'作业环境和时间影响风险（不能删除）'!$A$4:$B$9,2,FALSE)) -> 0
B28: 评分C2 | C28: ='作业环境和时间影响风险（不能删除）'!C3 -> 作业地段 | E28: 林区内作业，15分 | I28: =IF(ISERROR(VLOOKUP(E28,'作业环境和时间影响风险（不能删除）'!$C$4:$D$11,2,FALSE)),0,VLOOKUP(E28,'作业环境和时间影响风险（不能删除）'!$C$4:$D$11,2,FALSE)) -> 15
B29: 评分C3 | C29: ='作业环境和时间影响风险（不能删除）'!E3 -> 作业类型 | E29: 30米以上，10分 | I29: =IF(ISERROR(VLOOKUP(E29,'作业环境和时间影响风险（不能删除）'!$E$4:$F$10,2,FALSE)),0,VLOOKUP(E29,'作业环境和时间影响风险（不能删除）'!$E$4:$F$10,2,FALSE)) -> 10
B30: 评分C4 | C30: ='作业环境和时间影响风险（不能删除）'!G3 -> 作业时段 | E30: 正常时段作业，0分 | I30: =IF(ISERROR(VLOOKUP(E30,'作业环境和时间影响风险（不能删除）'!$G$4:$H$8,2,FALSE)),0,VLOOKUP(E30,'作业环境和时间影响风险（不能删除）'!$G$4:$H$8,2,FALSE)) -> 0
B31: 评分C5 | C31: ='作业环境和时间影响风险（不能删除）'!I3 -> 单日持续作业时长（疲劳度） | E31: 超过4小时但不超8小时，2分 | I31: =IF(ISERROR(VLOOKUP(E31,'作业环境和时间影响风险（不能删除）'!$I$4:$J$7,2,FALSE)),0,VLOOKUP(E31,'作业环境和时间影响风险（不能删除）'!$I$4:$J$7,2,FALSE)) -> 2
B32: 评分C6 | C32: ='作业环境和时间影响风险（不能删除）'!K3 -> 计划性质 | E32: 计划性工作，0分 | I32: =IF(ISERROR(VLOOKUP(E32,'作业环境和时间影响风险（不能删除）'!$K$4:$L$6,2,FALSE)),0,VLOOKUP(E32,'作业环境和时间影响风险（不能删除）'!$K$4:$L$6,2,FALSE)) -> 0
B33: 评分C7 | C33: ='作业环境和时间影响风险（不能删除）'!M3 -> 关键重要站点（线路） | E33: 非关键重要站点（线路），0分 | I33: =IF(ISERROR(VLOOKUP(E33,'作业环境和时间影响风险（不能删除）'!$M$4:$N$5,2,FALSE)),0,VLOOKUP(E33,'作业环境和时间影响风险（不能删除）'!$M$4:$N$5,2,FALSE)) -> 0

Sheet 典型作业项目库（不能删除）
A1: 广东电网有限责任公司生产现场作业风险管控业务指导书（2022版）附录C
A2: 序号 | B2: 作业类别 | C2: 作业任务 | D2: 基准风险值评分（A） | E2: 风险等级 | F2: 备注 | G2: （原）作业任务 | H2: （原）基准风险值评分（A） | I2: （原）风险等级
A3: 1 | B3: 安装、更换 | C3: 特殊条件下的导线（如特殊导线）拆除或更换新导线作业 | D3: 75 | E3: 中风险
A4: 2 | B4: 安装、更换 | C4: 架空线路停电检查、调整及更换导地线金具附件 | D4: 20 | E4: 低风险 | G4: 架空线路停电修补导地线 | H4: 20 | I4: 低风险
A5: 3 | B5: 安装、更换 | C5: 架空线路停电更换耐张自爆玻璃绝缘子 | D5: 20 | E5: 低风险 | G5: 架空线路停电清除导地线异物 | H5: 20 | I5: 低风险
A6: 4 | B6: 安装、更换 | C6: 架空线路停电调整及更换悬垂绝缘子 | D6: 20 | E6: 低风险 | G6: 架空线路停电装拆引流板或引流线 | H6: 20 | I6: 低风险
A7: 5 | B7: 安装、更换 | C7: 架空线路线路带电检查及更换地线金具附件 | D7: 20 | E7: 低风险 | G7: 架空线路杆塔构件补装 | H7: 20 | I7: 低风险
A8: 6 | B8: 安装、更换 | C8: 架空线路停电装拆引流板或引流线 | D8: 20 | E8: 低风险 | G8: 架空线路停电检查、调整及更换导地线金具附件 | H8: 20 | I8: 低风险
A9: 7 | B9: 安装、更换 | C9: 架空线路杆塔构件补装 | D9: 20 | E9: 低风险 | G9: 架空线路放撤导、地线 | H9: 30 | I9: 低风险
A10: 8 | B10: 安装、更换 | C10: 架空线路停电拆、装线路避雷器 | D10: 20 | E10: 低风险 | G10: 架空线路停电更换耐张自爆玻璃绝缘子 | H10: 20 | I10: 低风险
A11: 9 | B11: 安装、更换 | C11: 架空线路带电补装或更换杆塔标示牌 | D11: 20 | E11: 低风险 | G11: 架空线路停电调整及更换悬垂绝缘子 | H11: 20 | I11: 低风险
A12: 10 | B12: 安装、更换 | C12: 架空线路带电挂、取盐密样品 | D12: 20 | E12: 低风险 | G12: 架空线路调整拉线 | H12: 10 | I12: 可接受的风险
A13: 11 | B13: 安装、更换 | C13: 架空线路杆塔组立 | D13: 35 | E13: 低风险 | G13: 架空线路停电拆、装线路避雷器 | H13: 20 | I13: 低风险
A14: 12 | B14: 安装、更换 | C14: 架空线路停电放撤或更换导、地线 | D14: 30 | E14: 低风险 | G14: 架空线路线路带电检查及更换地线金具附件 | H14: 20 | I14: 低风险
A15: 13 | B15: 安装、更换 | C15: 架空线路停电安装或更换故障定位装置 | D15: 20 | E15: 低风险 | G15: 架空线路清除高杆植物 | H15: 35 | I15: 低风险
A16: 14 | B16: 安装、更换 | C16: 线路杆塔带电安装或更换视频监控装置 | D16: 20 | E16: 低风险
A17: 15 | B17: 安装、更换 | C17: 架空线路带电安装或更换微气象装置 | D17: 20 | E17: 低风险 | G17: 架空线路停电清抹、喷涂玻璃绝缘子 | H17: 20 | I17: 低风险
A18: 16 | B18: 安装、更换 | C18: 架空线路带电补装、更换杆塔附件或防护装置 | D18: 20 | E18: 低风险
A19: 17 | B19: 安装、更换 | C19: 架空线路等电位带电检查、调整及更换导地线金具附件 | D19: 30 | E19: 低风险
A20: 18 | B20: 安装、更换 | C20: 架空线路等电位带电更换耐张自爆玻璃绝缘子 | D20: 30 | E20: 低风险
A21: 19 | B21: 安装、更换 | C21: 架空线路等电位带电调整及更换悬垂绝缘子 | D21: 30 | E21: 低风险
A22: 20 | B22: 安装、更换 | C22: 架空线路等电位带电装拆引流板或引流线 | D22: 30 | E22: 低风险
A23: 21 | B23: 安装、更换 | C23: 退运线路杆塔、导线拆除作业 | D23: 30 | E23: 低风险 | G23: 架空线路带电补装或更换杆塔标示牌 | H23: 20 | I23: 低风险
A24: 22 | B24: 安装、更换 | C24: 架空线路更换拉线 | D24: 15 | E24: 可接受的风险 | G24: 架空线路带电挂、取盐密样品 | H24: 20 | I24: 低风险
A25: 23 | B25: 安装、更换 | C25: 架空线路调整拉线 | D25: 8 | E25: 可接受的风险 | G25: 架空线路带电清除鸟巢、飘挂物 | H25: 15 | I25: 可接受的风险
A26: 24 | B26: 安装、更换 | C26: 架空线路安装或更换基础位移监控装置 | D26: 8 | E26: 可接受的风险 | G26: 架空线路登塔检查 | H26: 20 | I26: 低风险
A27: 25 | B27: 安装、更换 | C27: 架空线路更换接地引下线 | D27: 15 | E27: 可接受的风险 | G27: 架空线路中间验收 | H27: 10 | I27: 可接受的风险
A28: 26 | B28: 安装、更换 | C28: 电缆安装或更换电缆环流监测装置 | D28: 8 | E28: 可接受的风险 | G28: 架空线路竣工验收 | H28: 10 | I28: 可接受的风险
A29: 27 | B29: 安装、更换 | C29: 电缆安装或更换电缆故障定位装置 | D29: 8 | E29: 可接受的风险
A30: 28 | B30: 安装、更换 | C30: 电缆安装或更换光纤测温装置 | D30: 8 | E30: 可接受的风险 | G30: 架空线路带电检查ADSS光缆金具附件作业 | H30: 20 | I30: 低风险
A31: 29 | B31: 安装、更换 | C31: 电缆避雷器更换 | D31: 8 | E31: 可接受的风险
A32: 30 | B32: 安装、更换 | C32: 电缆终端场或电缆通道地面（非高空作业）安装或更换视频监控装置 | D32: 7 | E32: 可接受的风险
A33: 31 | B33: 安装、更换 | C33: 电缆避雷器计数器带电更换 | D33: 20 | E33: 低风险 | G33: 架空线路杆塔组立 | H33: 35 | I33: 低风险
A34: 32 | B34: 安装、更换 | C34: 电缆线路安装或更换接地箱（带电） | D34: 20 | E34: 低风险 | G34: 架空线路带电补装或更换附件及监测设备 | H34: 20 | I34: 低风险
A35: 33 | B35: 安装、更换 | C35: 电缆线路安装或更换接地箱（停电） | D35: 5 | E35: 可接受的风险 | G35: 架空线路带电塔材除锈喷涂防腐油漆 | H35: 20 | I35: 低风险
A36: 34 | B36: 安装、更换 | C36: 架空线路安装、拆除ADSS光缆 | D36: 20 | E36: 低风险 | G36: 架空线路杆塔基础及护坡检修 | H36: 10 | I36: 可接受的风险
A37: 35 | B37: 安装、更换 | C37: 架空线路带电安装防鸟装置 | D37: 20 | E37: 低风险 | G37: 开挖深度超过 16m 的人工挖孔桩工程 | H37: 200 | I37: 高风险
A38: 36 | B38: 安装、更换 | C38: 架空线路带电补装或更换附件及监测设备 | D38: 20 | E38: 低风险 | G38: 开挖深度不超 16m 的人工挖扩孔桩（含掏挖桩） 工程 | H38: 75 | I38: 中风险
A39: 37 | B39: 安装、更换 | C39: 架空线路带电补装或更换杆塔相序牌 | D39: 20 | E39: 低风险 | G39: 普通基础开挖深度 5 米及以上 | H39: 200 | I39: 高风险
A40: 38 | B40: 安装、更换 | C40: 架空线路带电塔身安装鸟笼 | D40: 20 | E40: 低风险 | G40: 普通基础开挖深度 3-5 米 | H40: 75 | I40: 中风险
...

Sheet 作业人员能力（不能删除）
A2: B1 | C2: B2 | E2: B3 | G2: B4 | I2: B5 | K2: B6 | M2: B7 | O2: B8 | Q2: B9 | S2: B10
A3: 工作负责人（含小组工作负责人）安全意识 | B3: 评分 | C3: 主要工作班成员（辅助工除外）安全意识 | D3: 评分 | E3: 监护人（含专职监护人）安全意识 | F3: 评分 | G3: 作业总人数 | H3: 评分 | I3: 作业人员临时变更 | J3: 评分 | K3: 人员性质 | L3: 评分 | M3: 工作负责人（含小组工作负责人）组织同类型作业次数 | N3: 评分 | O3: 主要工作班成员（辅助工除外）参与同类型作业次数 | P3: 评分 | Q3: 监护人（含专职监护人）参与同类型作业次数 | R3: 评分 | S3: 作业人员精神状态、疲劳程度 | T3: 评分
A4: 3年内0-2次D类违章0分 | B4: 0 | C4: 3年内0-2次D类违章0分 | D4: 0 | E4: 3年内0-2次D类违章0分 | F4: 0 | G4: 不超过5人的，计0分 | H4: 0 | I4: 工作负责人在作业前（含工作间断后）1日确认的，计0分 | J4: 0 | K4: 本单位人员，0分 | L4: 0 | M4: 1年内2次及以上或2年内5次及以上的，每人计0分 | N4: 0 | O4: 1年内2次及以上或2年内5次及以上的，每人计0分 | P4: 0 | Q4: 1年内2次及以上或2年内5次及以上的，每人计0分 | R4: 0 | S4: 良好，计0分 | T4: 0
A5: 3年内累计3次及以上D类违章的，每人计2分 | B5: 2 | C5: 3年内累计3次及以上D类违章的，每人计2分 | D5: 2 | E5: 3年内累计3次及以上D类违章的，每人计2分 | F5: 2 | G5: 过5人但不足8人的，计1分 | H5: 1 | I5: 作业当日临时变更工作负责人，计5分 | J5: 5 | K5: 外施工单位人员，计5分 | L5: 5 | M5: 不满足上述要求，但累计5次及以上的，每人计2分 | N5: 2 | O5: 不满足上述要求，但累计5次及以上的，每人计2分 | P5: 2 | Q5: 不满足上述要求，但累计5次及以上的，每人计2分 | R5: 2 | S5: 一般，每人计2分 | T5: 2
A6: 3年内累计1次及以上C类违章的，每人计3分 | B6: 3 | C6: 3年内累计1次及以上C类违章的，每人计3分 | D6: 3 | E6: 3年内累计1次及以上C类违章的，每人计3分 | F6: 3 | G6: 超过8人但不足16人的，计3分 | H6: 3 | K6: 外施工单位劳务分包人员，计8分 | L6: 8 | M6: 累计不足5次但不小于3次的，每人计3分 | N6: 3 | O6: 累计不足5次但不小于3次的，每人计3分 | P6: 3 | Q6: 累计不足5次但不小于3次的，每人计3分 | R6: 3 | S6: 较差，每人计10分 | T6: 10
A7: 3年内累计1次及以上B类违章的，每人计5分 | B7: 5 | C7: 3年内累计1次以上B类违章的，每人计5分 | D7: 5 | E7: 3年内累计1次及以上B类违章的，每人计5分 | F7: 5 | G7: 超过16人但不足24人的，计5分 | H7: 5 | M7: 累计不足3次但不是第一次的，每人计5分 | N7: 5 | O7: 累计不足3次但不是第一次的，每人计5分 | P7: 5 | Q7: 累计不足3次但不是第一次的，每人计5分 | R7: 5 | S7: 很差，禁止作业 | T7: /
A8: 3年内累计1次及以上A类违章的，每人计6分 | B8: 6 | C8: 3年内累计1次及以上A类违章的，每人计6分 | D8: 6 | E8: 3年内累计1次及以上A类违章的，每人计6分 | F8: 6 | G8: 超过24人但不足50人的，计8分 | H8: 8 | M8: 第一次承担该类作业的，每人计6分 | N8: 6 | O8: 第一次参与该类作业的，每人计6分 | P8: 6 | Q8: 第一次监护该类作业的，每人计6分 | R8: 6
G9: 50人及以上的，计15分 | H9: 15

Sheet 作业环境和时间影响风险（不能删除）
A2: C1 | C2: C2 | E2: C3 | G2: C4 | I2: C5 | K2: C6 | M2: C7
A3: 天气 | B3: 评分 | C3: 作业地段 | D3: 评分 | E3: 作业类型 | F3: 评分 | G3: 作业时段 | H3: 评分 | I3: 单日持续作业时长（疲劳度） | J3: 评分 | K3: 计划性质 | L3: 评分 | M3: 关键重要站点（线路） | N3: 评分
A4: 天气舒适，0分 | B4: 0 | C4: 无特殊区段，0分 | D4: 0 | E4: 地面以上1.5米以下，0分 | F4: 0 | G4: 正常时段作业，0分 | H4: 0 | I4: 不超4小时，0分 | J4: 0 | K4: 计划性工作，0分 | L4: 0 | M4: 非关键重要站点（线路），0分 | N4: 0
A5: 户外作业小雨天气，10分 | B5: 10 | C5: 有限空间内作业：风、水、电和空气监测设施完备、信号传输正常的电缆隧道，3分； | D5: 3 | E5: 1.5米以上5米以下，2分 | F5: 2 | G5: 二级保供电期间涉及保供电设备的作业，5分 | H5: 5 | I5: 超过4小时但不超8小时，2分 | J5: 2 | K5: 提前一日制定的临时性作业任务，10分 | L5: 10 | M5: 关键重要站点（线路），5分 | N5: 5
A6: 户外作业4～5级大风，15分 | B6: 15 | C6: 有限空间内作业：风、水、电和空气监测设施不完备、信号传输不正常的电缆隧道，10分 | D6: 10 | E6: 5米以上15米以下，5分 | F6: 5 | G6: 站内或室内夜间作业(0点-次日6：00)，20分 | H6: 20 | I6: 超过8小时但不超12小时，10分 | J6: 10 | K6: 当日制定的临时性作业任务，20分 | L6: 20
A7: 气象部门发布蓝色天气预警信号后，户外作业受天气影响时，10分 | B7: 10 | C7: 有限空间环境当氧气不足或有毒有害气体含量超标时，禁止作业 | D7: / | E7: 15米以上30米以下，7分 | F7: 7 | G7: 站外线路夜间作业(20：00-次日6：00)，20分 | H7: 20 | I7: 超过12小时，20分 | J7: 20
A8: 气象部门发布黄色及以上天气预警信号后，户外作业受天气影响时，15分 | B8: 15 | C8: 作业区段内包含（双）多回共塔带电线路，10分 | D8: 10 | E8: 30米以上，10分 | F8: 10 | G8: 特级、一级保供电涉及保供电设备的作业、或春节等法定假日（含前后调休）期间作业，20分 | H8: 20
A9: 雷雨、雷电、风力大于五级时（台风、大风预警信号）不具备户外工作条件，不得工作 | B9: / | C9: 林区内作业，15分 | D9: 15 | E9: 动火作业，5分 | F9: 5
C10: 地质隐患区内作业，15分 | D10: 15 | E10: 大型吊装作业，5分 | F10: 5
C11: 可能造成导、地线、光缆脱落的作业，区段内包含重要交叉跨越、带电线路、临近易燃易爆、危险化学品场所等，30分 | D11: 30
